Workbook

Sheet 01_Candidate_Papers
A1: paper_id | B1: title | C1: authors | D1: year | E1: doi_or_url | F1: source_database | G1: screening_stage | H1: included | I1: exclusion_reason | J1: notes | K1: number_of_systems
A2: P001 | B2: Dolphin: Moving Towards Closed-loop Auto-research through Thinking, Practice, and Feedback | C2: Yuan et al. | D2: 2025 | E2: https://aclanthology.org/2025.acl-long.1056/ | G2: full_text | H2: 0 | I2: E4_Human_role_absent_or_incidental | J2: human role confined/not discussed
A3: P002 | B3: The AI Scientist-v2: Workshop-Level Automated Scientific Discovery via Agentic Tree Search | C3: Yamada et al. | D3: 2025 | E3: https://doi.org/10.48550/arXiv.2504.08066 | G3: full_text | H3: 1 | I3: N/A | K3: 1
A4: P003 | B4: Towards Scientific Discovery with Generative AI: Progress, Opportunities, and Challenges | C4: Reddy, C. K. and Shojaee, P. | D4: 2025 | E4: https://doi.org/10.1609/aaai.v39i27.35084 | G4: full_text | H4: 0 | I4: E3_No_concrete_system_or_evaluation | J4: perspective/position paper
A5: P004 | B5: AI-Researcher: Autonomous Scientific Innovation | C5: Tang et al. | D5: 2025 | E5: https://doi.org/10.48550/arXiv.2505.18705 | G5: full_text | H5: 1 | I5: N/A | K5: 1
A6: P005 | B6: Scientific discovery in the age of artificial intelligence | C6: Wang et al. | D6: 2023 | E6: https://doi.org/10.1038/s41586-023-06221-2 | G6: full_text | H6: 0 | I6: E3_No_concrete_system_or_evaluation | J6: perspective/position paper
A7: P006 | B7: From intention to implementation: automating biomedical research via LLMs | C7: Luo et al. | D7: 2025 | E7: https://doi.org/10.1007/s11432-024-4485-0 | G7: full_text | H7: 1 | I7: N/A | K7: 1
A8: P007 | B8: Towards end-to-end automation of AI research | C8: Lu et al. | D8: 2026 | E8: https://doi.org/10.1038/s41586-026-10265-5 | G8: full_text | H8: 1 | I8: N/A | K8: 1
A9: P008 | B9: LLM‐Based Agents for Tool Learning: A Survey | C9: Xu et al. | D9: 2025 | E9: https://doi.org/10.1007/s41019-025-00296-9 | G9: title_abstract | H9: 0 | I9: E1_Not_scientific_workflow
A10: P009 | B10: Automated statistical model discovery with language models | C10: Li et al. | D10: 2024 | E10: https://dl.acm.org/doi/10.5555/3692070.3693182 | G10: full_text | H10: 0 | I10: E4_Human_role_absent_or_incidental | J10: human contribution is only input/context supplied before automation
A11: P010 | B11: CodeScientist: End-to-End Semi-Automated Scientific Discovery with Code-based Experimentation | C11: Jansen et al. | D11: 2025 | E11: https://aclanthology.org/2025.findings-acl.692/ | G11: full_text | H11: 1 | I11: N/A | J11: HITL | K11: 1
A12: P011 | B12: Autonomous LLM-Driven Research — from Data to Human-Verifiable Research Papers | C12: Ifargan et al. | D12: 2024 | E12: https://ai.nejm.org/doi/full/10.1056/AIoa2400555 | G12: full_text | H12: 1 | I12: N/A | J12: human intervention in copilot mode | K12: 1
A13: P012 | B13: From AI for Science to Agentic Science: A Survey on Autonomous Scientific Discovery | C13: Wei et al. | D13: 2025 | E13: https://doi.org/10.48550/arXiv.2508.14111 | G13: full_text | H13: 0 | I13: E3_No_concrete_system_or_evaluation | J13: survey
A14: P013 | B14: Exploring the role of large language models in the scientific method: from hypothesis to discovery | C14: Zhang et al. | D14: 2025 | E14: https://doi.org/10.1038/s44387-025-00019-5 | G14: full_text | H14: 0 | I14: E3_No_concrete_system_or_evaluation | J14: perspective/position paper
A15: P014 | B15: Empowering Biomedical Discovery with AI Agents | C15: Gao et al. | D15: 2024 | E15: https://doi.org/10.1016/j.cell.2024.09.022 | G15: full_text | H15: 0 | I15: E3_No_concrete_system_or_evaluation | J15: perspective/position paper
A16: P015 | B16: Curie: Toward Rigorous and Automated Scientific Experimentation with AI Agents | C16: Kon et al. | D16: 2025 | E16: https://doi.org/10.48550/arXiv.2502.16069 | G16: full_text | H16: 1 | I16: N/A | K16: 1
A17: P016 | B17: AI4Research: A Survey of Artificial Intelligence for Scientific Research | C17: Chen et al. | D17: 2025 | E17: https://doi.org/10.48550/arXiv.2507.01903 | G17: full_text | H17: 0 | I17: E6_Other | J17: survey
A18: P017 | B18: Agentic AI and the rise of in silico team science in biomedical research | C18: Li et al. | D18: 2026 | E18: https://doi.org/10.1038/s41587-026-03035-1 | G18: full_text | H18: 0 | I18: E3_No_concrete_system_or_evaluation | J18: perspective/position paper
A19: P018 | B19: A Survey of AI Scientists | C19: Tie et al. | D19: 2026 | E19: https://doi.org/10.48550/arXiv.2510.23045 | G19: full_text | H19: 0 | I19: E6_Other | J19: survey
A20: P019 | B20: CycleResearcher: Improving Automated Research via Automated Review | C20: Weng et al. | D20: 2025 | E20: https://doi.org/10.48550/arXiv.2411.00816 | G20: full_text | H20: 1 | I20: N/A | K20: 2
A21: P020 | B21: WebGames: Challenging General-Purpose Web-Browsing AI Agents | C21: Thomas et al. | D21: 2025 | E21: https://doi.org/10.48550/arXiv.2502.18356 | G21: title_abstract | H21: 0 | I21: E1_Not_scientific_workflow
A22: P021 | B22: LLM-SR: Scientific Equation Discovery via Programming with Large Language Models | C22: Shojaee et al. | D22: 2025 | E22: https://doi.org/10.48550/arXiv.2404.18400 | G22: full_text | H22: 1 | I22: N/A | K22: 1
A23: P022 | B23: Search-o1: Agentic Search-Enhanced Large Reasoning Models | C23: Li et al. | D23: 2025 | E23: https://doi.org/10.48550/arXiv.2501.05366 | G23: title_abstract | H23: 0 | I23: E1_Not_scientific_workflow
A24: P023 | B24: ScoreFlow: Mastering LLM Agent Workflows via Score-based Preference Optimization | C24: Wang et al. | D24: 2025 | E24: https://doi.org/10.48550/arXiv.2502.04306 | G24: title_abstract | H24: 0 | I24: E5_Background_AI_capability_only
A25: P024 | B25: ARMAP: Scaling Autonomous Agents via Automatic Reward Modeling And Planning | C25: Chen et al. | D25: 2025 | E25: https://doi.org/10.48550/arXiv.2502.12130 | G25: title_abstract | H25: 0 | I25: E5_Background_AI_capability_only
A26: P025 | B26: Mathematical discoveries from program search with large language models | C26: Romera-Paredes et al. | D26: 2023 | E26: https://doi.org/10.1038/s41586-023-06924-6 | G26: full_text | H26: 1 | I26: N/A | K26: 1
A27: P026 | B27: Position: Agent Should Invoke External Tools ONLY When Epistemically Necessary | C27: Wang et al. | D27: 2026 | E27: https://doi.org/10.48550/arXiv.2506.00886 | G27: title_abstract | H27: 0 | I27: E1_Not_scientific_workflow
A28: P027 | B28: PlanGEN: A Multi-Agent Framework for Generating Planning and Reasoning Trajectories for Complex Problem Solving | C28: Parmar et al. | D28: 2025 | E28: https://doi.org/10.18653/v1/2025.emnlp-main.1042 | G28: title_abstract | H28: 0 | I28: E1_Not_scientific_workflow
A29: P028 | B29: PC-Agent: A Hierarchical Multi-Agent Collaboration Framework for Complex Task Automation on PC | C29: Liu et al. | D29: 2025 | E29: https://doi.org/10.48550/arXiv.2502.14282 | G29: title_abstract | H29: 0 | I29: E1_Not_scientific_workflow
A30: P029 | B30: OctoTools: An Agentic Framework with Extensible Tools for Complex Reasoning | C30: Lu et al. | D30: 2026 | E30: https://doi.org/10.48550/arXiv.2502.11271 | G30: title_abstract | H30: 0 | I30: E1_Not_scientific_workflow
A31: P030 | B31: AlphaEvolve: A coding agent for scientific and algorithmic discovery | C31: Novikov et al. | D31: 2025 | E31: https://doi.org/10.48550/arXiv.2506.13131 | G31: full_text | H31: 1 | I31: N/A | K31: 1
A32: P031 | B32: NovelSeek: When Agent Becomes the Scientist -- Building Closed-Loop System from Hypothesis to Verification | C32: Zhang et al. | D32: 2025 | E32: https://arxiv.org/abs/2505.16938v1 | G32: full_text | H32: 0 | I32: E6_Other | J32: outdated version
A33: P032 | B33: Multi-Agent Collaboration Mechanisms: A Survey of LLMs | C33: Trang et al. | D33: 2025 | E33: https://doi.org/10.48550/arXiv.2501.06322 | G33: title_abstract | H33: 0 | I33: E1_Not_scientific_workflow
A34: P033 | B34: MLGym: A New Framework and Benchmark for Advancing AI Research Agents | C34: Nathani et al. | D34: 2025 | E34: https://doi.org/10.48550/arXiv.2502.14499 | G34: full_text | H34: 0 | I34: E4_Human_role_absent_or_incidental | J34: human role confined to upstream framework/task design
A35: P034 | B35: Kosmos: An AI Scientist for Autonomous Discovery | C35: Mitchener et al. | D35: 2025 | E35: https://doi.org/10.48550/arXiv.2511.02824 | G35: full_text | H35: 1 | I35: N/A | K35: 1
A36: P035 | B36: Magma: A Foundation Model for Multimodal AI Agents | C36: Yang et al. | D36: 2025 | E36: https://doi.org/10.48550/arXiv.2502.13130 | G36: title_abstract | H36: 0 | I36: E1_Not_scientific_workflow
A37: P036 | B37: AIGS: Generating Science from AI-Powered Automated Falsification | C37: Liu et al. | D37: 2024 | E37: https://doi.org/10.48550/arXiv.2411.11910 | G37: full_text | H37: 1 | I37: N/A | K37: 1
A38: P037 | B38: DrugAgent: Automating AI-aided Drug Discovery Programming through LLM Multi-Agent Collaboration | C38: Liu et al. | D38: 2025 | E38: https://doi.org/10.48550/arXiv.2411.15692 | G38: full_text | H38: 1 | I38: N/A | K38: 1
A39: P038 | B39: Large Language Model based Multi-Agents: A Survey of Progress and Challenges | C39: Guo et al. | D39: 2024 | E39: https://dl.acm.org/doi/10.24963/ijcai.2024/890 | G39: title_abstract | H39: 0 | I39: E1_Not_scientific_workflow
A40: P039 | B40: DiscoveryWorld: A Virtual Environment for Developing and Evaluating Automated Scientific Discovery Agents | C40: Jansen et al. | D40: 2024 | E40: https://doi.org/10.52202/079017-0324 | G40: full_text | H40: 0 | I40: E4_Human_role_absent_or_incidental | J40: human role confined to upstream environment/task design
...

Sheet 02_Search_Log
A1: search_id | B1: database | C1: search_date | D1: exact_search_string | E1: filters | F1: results_returned | G1: notes
A2: S001
A3: S002
A4: S003
A5: S004
A6: S005
A7: S006
A8: S007
A9: S008
A10: S009
A11: S010

Sheet 03_Codebook
A1: variable | B1: value_or_code | C1: label | D1: operational_definition | E1: notes
A2: epistemic_mode | B2: PS | C2: Puzzle-solving in normal science | D2: Routine scientific work conducted within accepted paradigms, methods, assumptions, and evaluation criteria
A3: epistemic_mode | B3: AE | C3: Anomaly evaluation | D3: The assessment of unexpected findings, uncertain claims, or contested contributions to determine their credibility, significance, and relation to existing assumptions
A4: epistemic_mode | B4: PE | C4: Paradigm-shift exploration | D4: Exploratory work that searches for alternative concepts, frameworks, or research directions when existing assumptions may be insufficient
A5: alpha | B5: 0 | C5: None | D5: No task decomposition or coordination structure
A6: alpha | B6: 1 | C6: Fixed and predefined | D6: Fixed pipeline with predefined steps
A7: alpha | B7: 2 | C7: Dynamic | D7: Dynamic planning with explicit human checkpoints
A8: alpha | B8: 3 | C8: Adaptive | D8: Adaptive replanning across agents and humans, including handoffs, repair, and revision
A9: gamma | B9: 0 | C9: None | D9: No shared state or explicit task context
A10: gamma | B10: 1 | C10: Prompt-level | D10: Prompt-level task instruction only
A11: gamma | B11: 2 | C11: Explicit shared state | D11: Explicit shared memory, workspace, or task state
A12: gamma | B12: 3 | C12: High visibility and maintained common ground | D12: Shared assumptions, evidence, uncertainty, constraints, and role model are visible and maintained
A13: omega | B13: 0 | C13: Final output only | D13: Final output only
A14: omega | B14: 1 | C14: Visible traces | D14: Logs or execution traces are available
A15: omega | B15: 2 | C15: Intermediate visibility | D15: Intermediate states, provenance, and decision paths are visible
A16: omega | B16: 3 | C16: Contestable and intervenable | D16: Humans can inspect, contest, intervene, and revise system actions or outputs

Sheet 04_FinalCoding
A1: system_id | B1: paper_id | C1: system_name | D1: citation | E1: primary_workflow_stage | F1: epistemic_mode | G1: α | H1: γ | I1: ω | J1: evaluation_target | K1: failure_risk | L1: evidence_provenance | M1: coding_rationale

Sheet 05_Exclusion_Summary
A1: exclusion_code | B1: exclusion_reason | C1: title_abstract | D1: full_text | E1: total
A2: E1_Not_scientific_workflow | B2: Not relevant to scientific/research workflow | C2: =COUNTIFS('01_Candidate_Papers'!I2:I128, A2, '01_Candidate_Papers'!G2:G128,"title_abstract") -> 41 | D2: =COUNTIFS('01_Candidate_Papers'!I2:I128, A2, '01_Candidate_Papers'!G2:G128,"full_text") -> 3 | E2: =SUM(C2:D2) -> 44
A3: E2_No_agentic_or_collaborative_component | B3: No agentic or collaborative component | C3: =COUNTIFS('01_Candidate_Papers'!I2:I128, A3, '01_Candidate_Papers'!G2:G128,"title_abstract") -> 0 | D3: =COUNTIFS('01_Candidate_Papers'!I2:I128, A3, '01_Candidate_Papers'!G2:G128,"full_text") -> 0 | E3: =SUM(C3:D3) -> 0
A4: E3_No_concrete_system_or_evaluation | B4: No concrete system/benchmark/method/evaluation | C4: =COUNTIFS('01_Candidate_Papers'!I2:I128, A4, '01_Candidate_Papers'!G2:G128,"title_abstract") -> 0 | D4: =COUNTIFS('01_Candidate_Papers'!I2:I128, A4, '01_Candidate_Papers'!G2:G128,"full_text") -> 6 | E4: =SUM(C4:D4) -> 6
A5: E4_Human_role_absent_or_incidental | B5: Human involvement absent or incidental | C5: =COUNTIFS('01_Candidate_Papers'!I2:I128, A5, '01_Candidate_Papers'!G2:G128,"title_abstract") -> 0 | D5: =COUNTIFS('01_Candidate_Papers'!I2:I128, A5, '01_Candidate_Papers'!G2:G128,"full_text") -> 15 | E5: =SUM(C5:D5) -> 15
A6: E5_Background_AI_capability_only | B6: Background/general AI capability only | C6: =COUNTIFS('01_Candidate_Papers'!I2:I128, A6, '01_Candidate_Papers'!G2:G128,"title_abstract") -> 2 | D6: =COUNTIFS('01_Candidate_Papers'!I2:I128, A6, '01_Candidate_Papers'!G2:G128,"full_text") -> 0 | E6: =SUM(C6:D6) -> 2
A7: E6_Other | B7: Other | C7: =COUNTIFS('01_Candidate_Papers'!I2:I128, A7, '01_Candidate_Papers'!G2:G128,"title_abstract") -> 0 | D7: =COUNTIFS('01_Candidate_Papers'!I2:I128, A7, '01_Candidate_Papers'!G2:G128,"full_text") -> 6 | E7: =SUM(C7:D7) -> 6
A8: Total | C8: =SUM(C2:C7) -> 43 | D8: =SUM(D2:D7) -> 30 | E8: =SUM(E2:E7) -> 73
